<?xml version="1.0"?>
<robot name="ipharobov4">
    <!-- Robot center to the ground -->
    <link name="robot_footprint" />
    <!-- Base(Chassis)-->
    <link name="base_link">
        <pose>0 0 0.1 0 0 0</pose>
        <visual>
            <origin xyz="0 0 0.122405" rpy="0 0 0" />
            <geometry>
                <mesh filename="package://ipharobotv4_description/meshes/IPHARobot_Base.stl" scale="0.001 0.001 0.001" />
            </geometry>
        </visual>
        <collision>
            <origin xyz="0 0 0.122405" rpy="0 0 0" />
            <geometry>
                <box size="0.66602 0.72288 0.36481" />
            </geometry>
        </collision>
        <inertial name="box_inertial" params="0.66602 0.72288 0.36481 10.0">
            <mass value="${mass}" />
            <origin xyz="0 0 0" />
            <inertia ixx="${0.0833333 * mass * (y*y + z*z)}" ixy="0.0" ixz="0.0"
                iyy="${0.0833333 * mass * (x*x + z*z)}" iyz="0.0"
                izz="${0.0833333 * mass * (x*x + y*y)}" />
        </inertial>
    </link>

    <joint name="base_joint" type="fixed" >
        <origin xyz="0 0 0" rpy="0 0 0" />
        <parent link="robot_footprint" />
        <child link="base_link" />
    </joint>

    <!-- Wheels -->
    <link name='wheel_right_front_link'>
      <visual>
        <origin xyz="0 0 0" rpy=" 0 0 1.570796"/>
        <geometry>
          <mesh filename="package://ipharobotv4_description/meshes/IPHARobot_Wheel.stl" scale="0.001 0.001 0.001"/>
        </geometry>
      </visual>	 
      <collision>
        <origin xyz="0 0 0" rpy="0 1.570796 0 "/>
        <geometry>
          <cylinder radius="0.13" length="0.08"/>	  			  
        </geometry>
      </collision>
      <inertial name="cylinder_inertial" params="0.13 0.08 1.605">
        <mass value="${mass}" />
        <origin xyz="0 0 0" />
        <inertia ixx="${0.0833333 * mass * (3 * radius * radius + length * length)}" ixy="0.0" ixz="0.0"
          iyy="${0.0833333 * mass * (3 * radius * radius + length * length)}" iyz="0.0"
          izz="${0.5 * mass * radius * radius}" />
      </inertial>
    </link>

    <joint name="wheel_right_front_base" type="continuous">
      <origin xyz="0.29462 -0.163 0.0" rpy="-1.570796 0 0"/>
      <parent link="base_link"/>
      <child link="wheel_right_front_link"/>        
      <joint_properties damping="0.1" friction="0.1"/>
    </joint>

    <link name='wheel_left_front_link'>
      <visual>
        <origin xyz="0 0 0" rpy=" 0 0 1.570796"/>
        <geometry>
          <mesh filename="package://ipharobotv4_description/meshes/IPHARobot_Wheel.stl" scale="0.001 0.001 0.001"/>
        </geometry>
      </visual>	 
      <collision>
        <origin xyz="0 0 0" rpy="0 1.570796 0 "/>
        <geometry>
          <cylinder radius="0.13" length="0.08"/>	  			  
        </geometry>
      </collision>
      <inertial name="cylinder_inertial" params="0.13 0.08 1.605">
        <mass value="${mass}" />
        <origin xyz="0 0 0" />
        <inertia ixx="${0.0833333 * mass * (3 * radius * radius + length * length)}" ixy="0.0" ixz="0.0"
          iyy="${0.0833333 * mass * (3 * radius * radius + length * length)}" iyz="0.0"
          izz="${0.5 * mass * radius * radius}" />
      </inertial>
    </link>

    <joint name="wheel_left_front_base" type="continuous">
      <origin xyz="-0.29462 -0.163 0.0" rpy="-1.570796 0 0"/>
      <parent link="base_link"/>
      <child link="wheel_left_front_link"/>        
      <joint_properties damping="0.1" friction="0.1"/>
    </joint>

    <link name='wheel_right_back_link'>
      <visual>
        <origin xyz="0 0 0" rpy=" 0 0 1.570796"/>
        <geometry>
          <mesh filename="package://ipharobotv4_description/meshes/IPHARobot_Wheel.stl" scale="0.001 0.001 0.001"/>
        </geometry>
      </visual>	 
      <collision>
        <origin xyz="0 0 0" rpy="0 1.570796 0 "/>
        <geometry>
          <cylinder radius="0.13" length="0.08"/>	  			  
        </geometry>
      </collision>
      <inertial name="cylinder_inertial" params="0.13 0.08 1.605">
        <mass value="${mass}" />
        <origin xyz="0 0 0" />
        <inertia ixx="${0.0833333 * mass * (3 * radius * radius + length * length)}" ixy="0.0" ixz="0.0"
          iyy="${0.0833333 * mass * (3 * radius * radius + length * length)}" iyz="0.0"
          izz="${0.5 * mass * radius * radius}" />
      </inertial>
    </link>

    <joint name="wheel_right_back_base" type="continuous">
      <origin xyz="0.29462 0.163 0.0" rpy="-1.570796 0 0"/>
      <parent link="base_link"/>
      <child link="wheel_right_back_link"/>        
      <joint_properties damping="0.1" friction="0.1"/>
    </joint>

    <link name='wheel_left_back_link'>
      <visual>
        <origin xyz="0 0 0" rpy=" 0 0 1.570796"/>
        <geometry>
          <mesh filename="package://ipharobotv4_description/meshes/IPHARobot_Wheel.stl" scale="0.001 0.001 0.001"/>
        </geometry>
      </visual>	 
      <collision>
        <origin xyz="0 0 0" rpy="0 1.570796 0 "/>
        <geometry>
          <cylinder radius="0.13" length="0.08"/>	  			  
        </geometry>
      </collision>
      <inertial name="cylinder_inertial" params="0.13 0.08 1.605">
        <mass value="${mass}" />
        <origin xyz="0 0 0" />
        <inertia ixx="${0.0833333 * mass * (3 * radius * radius + length * length)}" ixy="0.0" ixz="0.0"
          iyy="${0.0833333 * mass * (3 * radius * radius + length * length)}" iyz="0.0"
          izz="${0.5 * mass * radius * radius}" />
      </inertial>
    </link>

    <joint name="wheel_left_back_base" type="continuous">
      <origin xyz="-0.29462 0.163 0.0" rpy="-1.570796 0 0"/>
      <parent link="base_link"/>
      <child link="wheel_left_back_link"/>        
      <joint_properties damping="0.1" friction="0.1"/>
    </joint>

    <!-- LIDAR -->
    <link name="scan_link" >
        <visual>
            <origin xyz="0 0 0" rpy="1.570796 0 -1.570796" />
            <geometry>
                <mesh filename="package://ipharobotv4_description/meshes/IPHARobot_YDLidar_G2.stl" scale="0.001 0.001 0.001" />
            </geometry>
        </visual>
        <collision>
            <origin xyz="0 0 0" rpy="1.570796 0 -1.570796" />
            <geometry>
                <cylinder radius="0.0737" length="0.0425"/>
            </geometry>
        </collision>
        <inertial name="cylinder_inertial" params="0.0737 0.0425 0.5">
          <mass value="${mass}" />
          <origin xyz="0 0 0" />
          <inertia ixx="${0.0833333 * mass * (3 * radius * radius + length * length)}" ixy="0.0" ixz="0.0"
           iyy="${0.0833333 * mass * (3 * radius * radius + length * length)}" iyz="0.0"
           izz="${0.5 * mass * radius * radius}" />
        </inertial>
    </link>

    <joint name="scan_joint" type="fixed">
        <origin xyz="0.045 0.21 0.322405" rpy="0 0 0" />
        <parent link="base_link" />
        <child link="scan_link" />
        <axis xyz="0 0 1" />
    </joint>

    <!--Zed_Camera Stereo Camera -->
    <link name="zed_camera_link">
        <visual>
            <origin xyz="0 0 0" rpy="0 0 0" />
            <geometry>
                <mesh filename="package://ipharobotv4_description/meshes/IPHARobot_Zedmini_Camera.stl" scale="0.001 0.001 0.001" />
            </geometry>
        </visual>
        <collision>
            <origin xyz="0 0 0" rpy="0 0 0" />
            <geometry>
                <box size="0.0305 0.01245 0.0265" />
            </geometry>
        </collision>
        <inertial name="box_inertial" params="0.0305 0.01245 0.0265 0.5">
            <mass value="${mass}" />
            <origin xyz="0 0 0" />
            <inertia ixx="${0.0833333 * mass * (y*y + z*z)}" ixy="0.0" ixz="0.0"
                iyy="${0.0833333 * mass * (x*x + z*z)}" iyz="0.0"
                izz="${0.0833333 * mass * (x*x + y*y)}" />
        </inertial>
    </link>

    <joint name="zed_camera_joint" type="fixed" >
        <origin xyz="0 -0.321 0.230905" rpy="0 0 0" />
        <parent link="base_link"/>
        <child link="zed_camera_link"/>
    </joint>

    <joint name="zed_camera_optical_left_joint" type="fixed">
         <origin xyz="0 0.01525 0" rpy="0 0 0" />
         <parent link="zed_camera_link" />
         <child link="zed_camera_optical_left_link" />
    </joint>

    <link name="zed_camera_optical_left_link" />

    <joint name="zed_camera_optical_right_joint" type="fixed">
         <origin xyz="0 -0.01525 0" rpy="0 0 0" />
         <parent link="zed_camera_link" />
         <child link="zed_camera_optical_right_link" />
    </joint>

    <link name="zed_camera_optical_right_link" />
    
    <!-- IMU Sensor -->
     <link name="imu_link">
        <visual>
            <origin xyz="0 0 0.127405" rpy="0 0 0" />
            <geometry>
                <mesh filename="package://ipharobotv4_description/meshes/IPHARobot_IMU.stl" scale="0.001 0.001 0.001"/>
            </geometry>
        </visual>
        <collision>
            <origin xyz="0 0 0.127405" rpy="0 0 0" />
            <geometry>
                <box size="0.026 0.0155 0.0016" />
            </geometry>
        </collision>
        <inertial name="box_inertial" params="0.026 0.0155 0.0016 0.001">
            <mass value="${mass}" />
            <origin xyz="0 0 0" />
            <inertia ixx="${0.0833333 * mass * (y*y + z*z)}" ixy="0.0" ixz="0.0"
                iyy="${0.0833333 * mass * (x*x + z*z)}" iyz="0.0"
                izz="${0.0833333 * mass * (x*x + y*y)}" />
        </inertial>
    </link>
        
    <joint name="imu_joint" type="fixed">
        <origin xyz="0 0 0.0016" rpy="0.0 0.0 0.0"/>
        <parent link="base_link"/>
        <child link="imu_link"/>
    </joint>
</robot>